Workbook

Sheet HandicapValues
A1: First Name | B1: Last Name | C1: Handicap | D1: Wins | E1: Losses | F1: Difference | G1: New Handicap | H1: Column1
A2: Andrew | B2: Spalding | C2: 45 | F2: =SUM(D2-E2) -> 0 | G2: =SUM(C2-(F2*5)) -> 45 | H2: =A2&" "&B2 -> Andrew Spalding
A3: Ben | B3: Cahill | C3: -25 | F3: =SUM(D3-E3) -> 0 | G3: =SUM(C3-(F3*5)) -> -25 | H3: =A3&" "&B3 -> Ben Cahill
A4: Corey | B4: Lee | C4: -15 | F4: =SUM(D4-E4) -> 0 | G4: =SUM(C4-(F4*5)) -> -15 | H4: =A4&" "&B4 -> Corey Lee
A5: Craig | B5: Bennett | C5: -160 | F5: =SUM(D5-E5) -> 0 | G5: =SUM(C5-(F5*5)) -> -160 | H5: =A5&" "&B5 -> Craig Bennett
A6: Dale | B6: Bridges | C6: -5 | F6: =SUM(D6-E6) -> 0 | G6: =SUM(C6-(F6*5)) -> -5 | H6: =A6&" "&B6 -> Dale Bridges
A7: David | B7: Palmer | C7: -110 | F7: =SUM(D7-E7) -> 0 | G7: =SUM(C7-(F7*5)) -> -110 | H7: =A7&" "&B7 -> David Palmer
A8: Eric | B8: Wolsley | C8: -150 | F8: =SUM(D8-E8) -> 0 | G8: =SUM(C8-(F8*5)) -> -150 | H8: =A8&" "&B8 -> Eric Wolsley
A9: Gavin | B9: Wilson | C9: 5 | F9: =SUM(D9-E9) -> 0 | G9: =SUM(C9-(F9*5)) -> 5 | H9: =A9&" "&B9 -> Gavin Wilson
A10: Geoff | B10: Challis | C10: 25 | F10: =SUM(D10-E10) -> 0 | G10: =SUM(C10-(F10*5)) -> 25 | H10: =A10&" "&B10 -> Geoff Challis
A11: Geoff | B11: Lockyer | C11: 25 | F11: =SUM(D11-E11) -> 0 | G11: =SUM(C11-(F11*5)) -> 25 | H11: =A11&" "&B11 -> Geoff Lockyer
A12: Gordon | B12: Males | C12: 65 | F12: =SUM(D12-E12) -> 0 | G12: =SUM(C12-(F12*5)) -> 65 | H12: =A12&" "&B12 -> Gordon Males
A13: Graeme | B13: Musgrove | C13: -10 | F13: =SUM(D13-E13) -> 0 | G13: =SUM(C13-(F13*5)) -> -10 | H13: =A13&" "&B13 -> Graeme Musgrove
... A40: Ron | B40: Callender | C40: -20 | F40: =SUM(D40-E40) -> 0 | G40: =SUM(C40-(F40*5)) -> -20 | H40: =A40&" "&B40 -> Ron Callender
A41: Ross | B41: Boag | C41: 50 | F41: =SUM(D40-E41) -> 0 | G41: =SUM(C41-(F41*5)) -> 50 | H41: =A41&" "&B41 -> Ross Boag
A42: Selwyn | B42: Lahey | C42: 85 | F42: =SUM(D41-E42) -> 0 | G42: =SUM(C42-(F42*5)) -> 85 | H42: =A42&" "&B42 -> Selwyn Lahey
A43: Shaune | B43: Hardy | C43: 45 | F43: =SUM(D43-E43) -> 0 | G43: =SUM(C43-(F43*5)) -> 45 | H43: =A43&" "&B43 -> Shaune Hardy
A44: Steve | B44: Bagshaw | C44: -180 | F44: =SUM(D44-E44) -> 0 | G44: =SUM(C44-(F44*5)) -> -180 | H44: =A44&" "&B44 -> Steve Bagshaw
A45: Stuart | B45: Page | C45: -5 | F45: =SUM(D45-E45) -> 0 | G45: =SUM(C45-(F45*5)) -> -5 | H45: =A45&" "&B45 -> Stuart Page
A46: Trevor | B46: Moore | C46: 55 | F46: =SUM(D46-E46) -> 0 | G46: =SUM(C46-(F46*5)) -> 55 | H46: =A46&" "&B46 -> Trevor Moore
A47: Wayne | B47: Clack | C47: -150 | F47: =SUM(D47-E47) -> 0 | G47: =SUM(C47-(F47*5)) -> -150 | H47: =A47&" "&B47 -> Wayne Clack

Sheet Handicaps
A1: 2022 - Billiards Handicaps Rounds 1 - 4
A3: Airport-1-W | D3: OCC-1 | G3: VRI-1-Wright | J3: Fill Ins
A5: David Palmer | B5: =LOOKUP(Handicaps!A5,Table1[Column1],Table1[New Handicap]) -> -110 | D5: Ivan Crowley | E5: =LOOKUP(Handicaps!D5,Table1[Column1],Table1[New Handicap]) -> -155 | G5: Graeme Wright | H5: =LOOKUP(Handicaps!G5,Table1[Column1],Table1[New Handicap]) -> -205 | J5: Mac Rynkiewicz | K5: =LOOKUP(Handicaps!J5,Table1[Column1],Table1[New Handicap]) -> -165
A6: Mick Williams | B6: =LOOKUP(Handicaps!A6,Table1[Column1],Table1[New Handicap]) -> -100 | D6: Wayne Clack | E6: =LOOKUP(Handicaps!D6,Table1[Column1],Table1[New Handicap]) -> -150 | G6: Jayson McLean | H6: =LOOKUP(Handicaps!G6,Table1[Column1],Table1[New Handicap]) -> -110 | J6: Shaune Hardy | K6: =LOOKUP(Handicaps!J6,Table1[Column1],Table1[New Handicap]) -> 45
A7: Eric Worsley | B7: =LOOKUP(Handicaps!A7,Table1[Column1],Table1[New Handicap]) -> -150 | D7: John Lewis | E7: =LOOKUP(Handicaps!D7,Table1[Column1],Table1[New Handicap]) -> -80 | G7: Jason Smiley | H7: =LOOKUP(Handicaps!G7,Table1[Column1],Table1[New Handicap]) -> -20 | J7: Gordon Males | K7: =LOOKUP(Handicaps!J7,Table1[Column1],Table1[New Handicap]) -> 65
A8: Ben Cahill | B8: =LOOKUP(Handicaps!A8,Table1[Column1],Table1[New Handicap]) -> -25 | D8: Jason Crocker | E8: =LOOKUP(Handicaps!D8,Table1[Column1],Table1[New Handicap]) -> -20 | G8: Stuart Page | H8: =LOOKUP(Handicaps!G8,Table1[Column1],Table1[New Handicap]) -> -5
D9: John Grubb | E9: =LOOKUP(Handicaps!D9,Table1[Column1],Table1[New Handicap]) -> -40 | G9: Trevor Moore | H9: =LOOKUP(Handicaps!G9,Table1[Column1],Table1[New Handicap]) -> 55
D10: Selwyn Lahey | E10: =LOOKUP(Handicaps!D10,Table1[Column1],Table1[New Handicap]) -> 85
A13: Airport-2-G | D13: OCC-2 | G13: VRI-2-Bridges
A15: Steve Bagshaw | B15: =LOOKUP(Handicaps!A15,Table1[Column1],Table1[New Handicap]) -> -180 | D15: John Eltringham | E15: =LOOKUP(Handicaps!D15,Table1[Column1],Table1[New Handicap]) -> -165 | G15: Rohan Liston | H15: =LOOKUP(Handicaps!G15,Table1[Column1],Table1[New Handicap]) -> -70
A16: Craig Bennett | B16: =LOOKUP(Handicaps!A16,Table1[Column1],Table1[New Handicap]) -> -160 | D16: Geoff Lockyer | E16: =LOOKUP(Handicaps!D16,Table1[Column1],Table1[New Handicap]) -> 25 | G16: Neville Harty | H16: =LOOKUP(Handicaps!G16,Table1[Column1],Table1[New Handicap]) -> -35
A17: Rod Mc Callum | B17: =LOOKUP(Handicaps!A17,Table1[Column1],Table1[New Handicap]) -> -110 | D17: Peter Oates | E17: =LOOKUP(Handicaps!D17,Table1[Column1],Table1[New Handicap]) -> 25 | G17: Ron Callender | H17: =LOOKUP(Handicaps!G17,Table1[Column1],Table1[New Handicap]) -> -20
A18: Las Ifca | B18: =LOOKUP(Handicaps!A18,Table1[Column1],Table1[New Handicap]) -> -130 | D18: Geoff Challis | E18: =LOOKUP(Handicaps!D18,Table1[Column1],Table1[New Handicap]) -> 25 | G18: Graeme Musgrove | H18: =LOOKUP(Handicaps!G18,Table1[Column1],Table1[New Handicap]) -> -10
A19: Mitch Calnin | B19: =LOOKUP(Handicaps!A19,Table1[Column1],Table1[New Handicap]) -> -80 | G19: Corey Lee | H19: =LOOKUP(Handicaps!G19,Table1[Column1],Table1[New Handicap]) -> -15
A20: Rob Young | B20: =LOOKUP(Handicaps!A20,Table1[Column1],Table1[New Handicap]) -> -80 | G20: Dale Bridges | H20: =LOOKUP(Handicaps!G20,Table1[Column1],Table1[New Handicap]) -> -5
A21: Rod Vincent | B21: =LOOKUP(Handicaps!A21,Table1[Column1],Table1[New Handicap]) -> -70 | G21: Ross Boag | H21: =LOOKUP(Handicaps!G21,Table1[Column1],Table1[New Handicap]) -> 50
J25: Not playing
J27: Greg Allison | K27: =LOOKUP(Handicaps!J27,Table1[Column1],Table1[New Handicap]) -> -55
J28: Ian Boyle | K28: =LOOKUP(Handicaps!J28,Table1[Column1],Table1[New Handicap]) -> -50
J29: Matthew White | K29: =LOOKUP(Handicaps!J29,Table1[Column1],Table1[New Handicap]) -> -35
J30: Gavin Wilson | K30: =LOOKUP(Handicaps!J30,Table1[Column1],Table1[New Handicap]) -> 5
J31: Ian Benton | K31: =LOOKUP(Handicaps!J31,Table1[Column1],Table1[New Handicap]) -> 20
J32: Roger Jones | K32: =LOOKUP(Handicaps!J32,Table1[Column1],Table1[New Handicap]) -> 35
J33: Ray Letcher | K33: =LOOKUP(Handicaps!J33,Table1[Column1],Table1[New Handicap]) -> 40
J34: Phil Paige | K34: =LOOKUP(Handicaps!J34,Table1[Column1],Table1[New Handicap]) -> 50
J35: Ray Wilson | K35: =LOOKUP(Handicaps!J35,Table1[Column1],Table1[New Handicap]) -> 105

Sheet BilliardStats
F2: BBSA Inc. 2022 Billiards Season
A4: Player | B4: Won | C4: Lost | D4: Dif. | F4: 1 | G4: 2 | H4: 3 | I4: 4 | J4: 5 | K4: 6 | L4: 7 | M4: 8 | N4: 9 | O4: 10 | P4: 11 | Q4: 12 | R4: 13 | S4: 14 | T4: 15 | U4: % | V4: Hcp | W4: => 20 | X4: HB
A5: Airport-1-W | B5: =SUM(B6:B10) -> 0 | C5: =SUM(C6:C10) -> 0 | D5: =SUM(B5-C5) -> 0 | F5: =COUNTIF(F6:F9,"w") -> 0 | G5: =COUNTIF(G6:G9,"w") -> 0 | H5: =COUNTIF(H6:H9,"w") -> 0 | I5: =COUNTIF(I6:I9,"w") -> 0 | J5: =COUNTIF(J6:J9,"w") -> 0 | K5: =COUNTIF(K6:K9,"w") -> 0 | L5: =COUNTIF(L6:L9,"w") -> 0 | M5: =COUNTIF(M6:M9,"w") -> 0 | ... T5: =COUNTIF(T6:T9,"w") -> 0
A6: David Palmer | B6: =COUNTIF(F6:T6,"w") -> 0 | C6: =COUNTIF(F6:T6,"l") -> 0 | D6: =SUM(B6-C6) -> 0 | U6: =B6/(B6+C6) -> #DIV/0! | V6: =LOOKUP(A6,HandicapValues!H:H,HandicapValues!G:G) -> -110
A7: Mick Williams | B7: =COUNTIF(F7:T7,"w") -> 0 | C7: =COUNTIF(F7:T7,"l") -> 0 | D7: =SUM(B7-C7) -> 0 | U7: =B7/(B7+C7) -> #DIV/0! | V7: =LOOKUP(A7,HandicapValues!H:H,HandicapValues!G:G) -> -100
A8: Eric Wolsley | B8: =COUNTIF(F8:T8,"w") -> 0 | C8: =COUNTIF(F8:T8,"l") -> 0 | D8: =SUM(B8-C8) -> 0 | U8: =B8/(B8+C8) -> #DIV/0! | V8: =LOOKUP(A8,HandicapValues!H:H,HandicapValues!G:G) -> -150
A9: Ben Cahill | B9: =COUNTIF(F9:T9,"w") -> 0 | C9: =COUNTIF(F9:T9,"l") -> 0 | D9: =SUM(B9-C9) -> 0 | U9: =B9/(B9+C9) -> #DIV/0! | V9: =LOOKUP(A9,HandicapValues!H:H,HandicapValues!G:G) -> -25
B10: =COUNTIF(F10:T10,"w") -> 0 | C10: =COUNTIF(F10:T10,"l") -> 0 | D10: =SUM(B10-C10) -> 0
A11: Airport-2-G | B11: =SUM(B12:B19) -> 0 | C11: =SUM(C12:C19) -> 0 | D11: =SUM(B11-C11) -> 0 | F11: =COUNTIF(F12:F18,"w") -> 0 | G11: =COUNTIF(G12:G18,"w") -> 0 | H11: =COUNTIF(H12:H18,"w") -> 0 | I11: =COUNTIF(I12:I18,"w") -> 0 | J11: =COUNTIF(J12:J18,"w") -> 0 | K11: =COUNTIF(K12:K18,"w") -> 0 | L11: =COUNTIF(L12:L18,"w") -> 0 | M11: =COUNTIF(M12:M18,"w") -> 0 | ... T11: =COUNTIF(T12:T18,"w") -> 0
A12: Steve Bagshaw | B12: =COUNTIF(F12:T12,"w") -> 0 | C12: =COUNTIF(F12:T12,"l") -> 0 | D12: =SUM(B12-C12) -> 0 | U12: =B12/(B12+C12) -> #DIV/0! | V12: =LOOKUP(A12,HandicapValues!H:H,HandicapValues!G:G) -> -180
A13: Craig Bennett | B13: =COUNTIF(F13:T13,"w") -> 0 | C13: =COUNTIF(F13:T13,"l") -> 0 | D13: =SUM(B13-C13) -> 0 | U13: =B13/(B13+C13) -> #DIV/0! | V13: =LOOKUP(A13,HandicapValues!H:H,HandicapValues!G:G) -> -160
A14: Rod Mc Callum | B14: =COUNTIF(F14:T14,"w") -> 0 | C14: =COUNTIF(F14:T14,"l") -> 0 | D14: =SUM(B14-C14) -> 0 | U14: =B14/(B14+C14) -> #DIV/0! | V14: =LOOKUP(A14,HandicapValues!H:H,HandicapValues!G:G) -> -110
A15: Las Ifca | B15: =COUNTIF(F15:T15,"w") -> 0 | C15: =COUNTIF(F15:T15,"l") -> 0 | D15: =SUM(B15-C15) -> 0 | U15: =B15/(B15+C15) -> #DIV/0! | V15: =LOOKUP(A15,HandicapValues!H:H,HandicapValues!G:G) -> -130
A16: Mitch Calnin | B16: =COUNTIF(F16:T16,"w") -> 0 | C16: =COUNTIF(F16:T16,"l") -> 0 | D16: =SUM(B16-C16) -> 0 | U16: =B16/(B16+C16) -> #DIV/0! | V16: =LOOKUP(A16,HandicapValues!H:H,HandicapValues!G:G) -> -80
A17: Rob Young | B17: =COUNTIF(F17:T17,"w") -> 0 | C17: =COUNTIF(F17:T17,"l") -> 0 | D17: =SUM(B17-C17) -> 0 | U17: =B17/(B17+C17) -> #DIV/0! | V17: =LOOKUP(A17,HandicapValues!H:H,HandicapValues!G:G) -> -80
A18: Rod Vincent | B18: =COUNTIF(F18:T18,"w") -> 0 | C18: =COUNTIF(F18:T18,"l") -> 0 | D18: =SUM(B18-C18) -> 0 | U18: =B18/(B18+C18) -> #DIV/0! | V18: =LOOKUP(A18,HandicapValues!H:H,HandicapValues!G:G) -> -70
B19: =COUNTIF(F19:T19,"w") -> 0 | C19: =COUNTIF(F19:T19,"l") -> 0 | D19: =SUM(B19-C19) -> 0
A20: OCC-1 | B20: =SUM(B21:B27) -> 0 | C20: =SUM(C21:C27) -> 0 | D20: =SUM(B20-C20) -> 0 | F20: =COUNTIF(F21:F27,"w") -> 0 | G20: =COUNTIF(G21:G27,"w") -> 0 | H20: =COUNTIF(H21:H27,"w") -> 0 | I20: =COUNTIF(I21:I27,"w") -> 0 | J20: =COUNTIF(J21:J27,"w") -> 0 | K20: =COUNTIF(K21:K27,"w") -> 0 | L20: =COUNTIF(L21:L27,"w") -> 0 | M20: =COUNTIF(M21:M27,"w") -> 0 | ... T20: =COUNTIF(T21:T27,"w") -> 0
A21: Ivan Crowley | B21: =COUNTIF(F21:T21,"w") -> 0 | C21: =COUNTIF(F21:T21,"l") -> 0 | D21: =SUM(B21-C21) -> 0 | U21: =B21/(B21+C21) -> #DIV/0! | V21: =LOOKUP(A21,HandicapValues!H:H,HandicapValues!G:G) -> -155
A22: Wayne Clack | B22: =COUNTIF(F22:T22,"w") -> 0 | C22: =COUNTIF(F22:T22,"l") -> 0 | D22: =SUM(B22-C22) -> 0 | U22: =B22/(B22+C22) -> #DIV/0! | V22: =LOOKUP(A22,HandicapValues!H:H,HandicapValues!G:G) -> -150
A23: John Lewis | B23: =COUNTIF(F23:T23,"w") -> 0 | C23: =COUNTIF(F23:T23,"l") -> 0 | D23: =SUM(B23-C23) -> 0 | U23: =B23/(B23+C23) -> #DIV/0! | V23: =LOOKUP(A23,HandicapValues!H:H,HandicapValues!G:G) -> -80
A24: Jason Crocker | B24: =COUNTIF(F24:T24,"w") -> 0 | C24: =COUNTIF(F24:T24,"l") -> 0 | D24: =SUM(B24-C24) -> 0 | U24: =B24/(B24+C24) -> #DIV/0! | V24: =LOOKUP(A24,HandicapValues!H:H,HandicapValues!G:G) -> -20
A25: John Grubb | B25: =COUNTIF(F25:T25,"w") -> 0 | C25: =COUNTIF(F25:T25,"l") -> 0 | D25: =SUM(B25-C25) -> 0 | U25: =B25/(B25+C25) -> #DIV/0! | V25: =LOOKUP(A25,HandicapValues!H:H,HandicapValues!G:G) -> -40
A26: Selwyn Lahey | B26: =COUNTIF(F26:T26,"w") -> 0 | C26: =COUNTIF(F26:T26,"l") -> 0 | D26: =SUM(B26-C26) -> 0 | U26: =B26/(B26+C26) -> #DIV/0! | V26: =LOOKUP(A26,HandicapValues!H:H,HandicapValues!G:G) -> 85
B27: =COUNTIF(F27:T27,"w") -> 0 | C27: =COUNTIF(F27:T27,"l") -> 0 | D27: =SUM(B27-C27) -> 0
A28: OCC-2 | B28: =SUM(B29:B33) -> 0 | C28: =SUM(C29:C33) -> 0 | D28: =SUM(B28-C28) -> 0 | F28: =COUNTIF(F29:F32,"w") -> 0 | G28: =COUNTIF(G29:G32,"w") -> 0 | H28: =COUNTIF(H29:H32,"w") -> 0 | I28: =COUNTIF(I29:I32,"w") -> 0 | J28: =COUNTIF(J29:J32,"w") -> 0 | K28: =COUNTIF(K29:K32,"w") -> 0 | L28: =COUNTIF(L29:L32,"w") -> 0 | M28: =COUNTIF(M29:M32,"w") -> 0 | ... T28: =COUNTIF(T29:T32,"w") -> 0
A29: John Eltringham | B29: =COUNTIF(F29:T29,"w") -> 0 | C29: =COUNTIF(F29:T29,"l") -> 0 | D29: =SUM(B29-C29) -> 0 | U29: =B29/(B29+C29) -> #DIV/0! | V29: =LOOKUP(A29,HandicapValues!H:H,HandicapValues!G:G) -> -165
A30: Geoff Lockyer | B30: =SUM(F30:T30) -> 0 | C30: =COUNT(F30:T30)*3-B30 -> 0 | D30: =SUM(B30-C30) -> 0 | U30: =B30/(B30+C30) -> #DIV/0! | V30: =LOOKUP(A30,HandicapValues!H:H,HandicapValues!G:G) -> 25
A31: Peter Oates | B31: =SUM(F31:T31) -> 0 | C31: =COUNT(F31:T31)*3-B31 -> 0 | D31: =SUM(B31-C31) -> 0 | U31: =B31/(B31+C31) -> #DIV/0! | V31: =LOOKUP(A31,HandicapValues!H:H,HandicapValues!G:G) -> 25
A32: Geoff Challis | B32: =SUM(F32:T32) -> 0 | C32: =COUNT(F32:T32)*3-B32 -> 0 | D32: =SUM(B32-C32) -> 0 | U32: =B32/(B32+C32) -> #DIV/0! | V32: =LOOKUP(A32,HandicapValues!H:H,HandicapValues!G:G) -> 25
B33: =COUNTIF(F33:T33,"w") -> 0 | C33: =COUNTIF(F33:T33,"l") -> 0 | D33: =SUM(B33-C33) -> 0
A34: VRI-1-W | B34: =SUM(B35:B40) -> 0 | C34: =SUM(C35:C40) -> 0 | D34: =SUM(B34-C34) -> 0 | F34: =COUNTIF(F35:F39,"w") -> 0 | G34: =COUNTIF(G35:G39,"w") -> 0 | H34: =COUNTIF(H35:H39,"w") -> 0 | I34: =COUNTIF(I35:I39,"w") -> 0 | J34: =COUNTIF(J35:J39,"w") -> 0 | K34: =COUNTIF(K35:K39,"w") -> 0 | L34: =COUNTIF(L35:L39,"w") -> 0 | M34: =COUNTIF(M35:M39,"w") -> 0 | ... T34: =COUNTIF(T35:T39,"w") -> 0
A35: Graeme Wright | B35: =COUNTIF(F35:T35,"w") -> 0 | C35: =COUNTIF(F35:T35,"l") -> 0 | D35: =SUM(B35-C35) -> 0 | U35: =B35/(B35+C35) -> #DIV/0! | V35: =LOOKUP(A35,HandicapValues!H:H,HandicapValues!G:G) -> -205
A36: Jayson McLean | B36: =COUNTIF(F36:T36,"w") -> 0 | C36: =COUNTIF(F36:T36,"l") -> 0 | D36: =SUM(B36-C36) -> 0 | U36: =B36/(B36+C36) -> #DIV/0! | V36: =LOOKUP(A36,HandicapValues!H:H,HandicapValues!G:G) -> -110
A37: Jason Smiley | B37: =COUNTIF(F37:T37,"w") -> 0 | C37: =COUNTIF(F37:T37,"l") -> 0 | D37: =SUM(B37-C37) -> 0 | U37: =B37/(B37+C37) -> #DIV/0! | V37: =LOOKUP(A37,HandicapValues!H:H,HandicapValues!G:G) -> -20
A38: Stuart Page | B38: =COUNTIF(F38:T38,"w") -> 0 | C38: =COUNTIF(F38:T38,"l") -> 0 | D38: =SUM(B38-C38) -> 0 | U38: =B38/(B38+C38) -> #DIV/0! | V38: =LOOKUP(A38,HandicapValues!H:H,HandicapValues!G:G) -> -5
A39: Trevor Moore | B39: =COUNTIF(F39:T39,"w") -> 0 | C39: =COUNTIF(F39:T39,"l") -> 0 | D39: =SUM(B39-C39) -> 0 | U39: =B39/(B39+C39) -> #DIV/0! | V39: =LOOKUP(A39,HandicapValues!H:H,HandicapValues!G:G) -> 55
B40: =COUNTIF(F40:T40,"w") -> 0 | C40: =COUNTIF(F40:T40,"l") -> 0 | D40: =SUM(B40-C40) -> 0
A41: VRI-2-B | B41: =SUM(B42:B49) -> 0 | C41: =SUM(C42:C49) -> 0 | D41: =SUM(B41-C41) -> 0 | F41: =COUNTIF(F42:F45,"w") -> 0 | G41: =COUNTIF(G42:G45,"w") -> 0 | H41: =COUNTIF(H42:H45,"w") -> 0 | I41: =COUNTIF(I42:I45,"w") -> 0 | J41: =COUNTIF(J42:J45,"w") -> 0 | K41: =COUNTIF(K42:K45,"w") -> 0 | L41: =COUNTIF(L42:L45,"w") -> 0 | M41: =COUNTIF(M42:M45,"w") -> 0 | ... T41: =COUNTIF(T42:T45,"w") -> 0
A42: Rohan Liston | B42: =COUNTIF(F42:T42,"w") -> 0 | C42: =COUNTIF(F42:T42,"l") -> 0 | D42: =SUM(B42-C42) -> 0 | U42: =B42/(B42+C42) -> #DIV/0! | V42: =LOOKUP(A42,HandicapValues!H:H,HandicapValues!G:G) -> -70
...

Sheet Teams
A1: Team | B1: Player 1 | C1: Player 2 | D1: Player 3 | E1: Player 4 | F1: Player 5 | G1: Player 6 | H1: Player 7
A2: Airport-1-W | B2: David Palmer | C2: Mick Williams | D2: Eric Worsley | E2: Ben Cahill
A3: Airport-2-G | B3: Steve Bagshaw | C3: Craig Bennett | D3: Rod Mc Callum | E3: Las Ifca | F3: Mitch Calnin | G3: Rob Young | H3: Rod Vincent
A4: OCC-1 | B4: Ivan Crowley | C4: Wayne Clack | D4: John Lewis | E4: Jason Crocker | F4: John Grubb | G4: Selwyn Lahey
A5: OCC-2 | B5: John Eltringham | C5: Geoff Lockyer | D5: Peter Oates | E5: Geoff Challis
A6: VRI-1-Wright | B6: Graeme Wright | C6: Jayson McLean | D6: Jason Smiley | E6: Stuart Page | F6: Trevor Moore
A7: VRI-2-Bridges | B7: Rohan Liston | C7: Neville Harty | D7: Ron Callender | E7: Graeme Musgrove | F7: Corey Lee | G7: Dale Bridges | H7: Ross Boag
A9: Defeated
A10: Drew with
A11: Lost to

Sheet BilliardResults R1
C2: BBSA Billiards 2022 - Round 1
A4: Team | B4: Matches Won | C4: Matches Lost | D4: Games Won | E4: Games Lost | F4: Prem.Points | G4: Points For | H4: Points Against | I4: Pts %
A5: OCC-2 | B5: 1 | C5: 0 | D5: 4 | E5: 0 | F5: =SUM(B5*2+D5*2) -> 10 | G5: 1240 | H5: 883 | I5: =G5/H5 -> 1.4043035
A6: Airport-1-W | B6: 1 | C6: 0 | D6: 4 | E6: 0 | F6: =SUM(B6*2+D6*2) -> 10 | G6: 1028 | H6: 894 | I6: =G6/H6 -> 1.1498881
A7: VRI-2-Bridges | B7: 1 | C7: 0 | D7: 3 | E7: 1 | F7: =SUM(B7*2+D7*2) -> 8 | G7: 1094 | H7: 893 | I7: =G7/H7 -> 1.225084
A8: OCC-1 | B8: 0 | C8: 1 | D8: 1 | E8: 3 | F8: =SUM(B8*2+D8*2) -> 2 | G8: 893 | H8: 1094 | I8: =G8/H8 -> 0.81627057
A9: VRI-1-Wright | B9: 0 | C9: 1 | D9: 0 | E9: 4 | F9: =SUM(B9*2+D9*2) -> 0 | G9: 894 | H9: 1028 | I9: =G9/H9 -> 0.86964981
A10: Airport-2-G | B10: 0 | C10: 1 | D10: 0 | E10: 4 | F10: =SUM(B10*2+D10*2) -> 0 | G10: 883 | H10: 1240 | I10: =G10/H10 -> 0.71209677
A13: Round 1
A14: Breaks +20 | B14: Airport-1-W | C14: 4 | D14: Defeated | E14: VRI-1-Wright | F14: 0 | G14: Breaks +20
A15: 25,27 | B15: Eric Worsley | C15: 279 | D15: Defeated | E15: Graeme Wright | F15: 255 | G15: 37,31
A16: 39,24 | B16: Mick Williams | C16: 243 | D16: Defeated | E16: Jason Smiley | F16: 213
A17: 36,20 | B17: David Palmer | C17: 262 | D17: Defeated | E17: Stuart Page | F17: 230
B18: Ben Cahill | C18: 244 | D18: Defeated | E18: Trevor Moore | F18: 196
C19: =SUM(C15:C18) -> 1028 | F19: =SUM(F15:F18) -> 894
B21: VRI-2-Bridges | C21: 3 | D21: Defeated | E21: OCC-1 | F21: 1
B22: Neville Harty | C22: 301 | D22: Defeated | E22: Ivan Crowley | F22: 195
A23: 25 | B23: Ron Callender | C23: 310 | D23: Defeated | E23: Wayne Clack | F23: 207 | G23: 27,21
B24: Corey Lee | C24: 211 | D24: Lost to | E24: John Lewis | F24: 223
B25: Graeme Musgrove | C25: 272 | D25: Defeated | E25: John Grubb | F25: 268
C26: =SUM(C22:C25) -> 1094 | F26: =SUM(F22:F25) -> 893
B28: OCC-2 | C28: 4 | D28: Defeated | E28: Airport-2-G | F28: 0
A29: 24,26,21,26 | B29: John Eltringham | C29: 354 | D29: Defeated | E29: Steve Bagshaw | F29: 262 | G29: 32,36
B30: Geoff Challis | C30: 335 | D30: Defeated | E30: Craig Bennett | F30: 252 | G30: 25,24,22
B31: Peter Oates | C31: 291 | D31: Defeated | E31: Rod Mc Callum | F31: 233
B32: Geoff Lockyer | C32: 260 | D32: Defeated | E32: Rob Young | F32: 136
C33: =SUM(C29:C32) -> 1240 | F33: =SUM(F29:F32) -> 883

Sheet BilliardResults R2
E2: BBSA Billiards 2022 - Round 1
A3: Team | B3: Matches Won | C3: Matches Lost | D3: Games Won | E3: Games Lost | F3: Prem.Points | G3: Points For | H3: Points Against | I3: Pts %
A4: A.Williams | F4: =SUM(B4*2+D4*2) -> 0 | I4: =G4/H4 -> #DIV/0!
A5: OCC-2 | F5: =SUM(B5*2+D5*2) -> 0 | I5: =G5/H5 -> #DIV/0!
A6: VRI-Mac | F6: =SUM(B6*2+D6*2) -> 0 | I6: =G6/H6 -> #DIV/0!
A7: OCC-1 | F7: =SUM(B7*2+D7*2) -> 0 | I7: =G7/H7 -> #DIV/0!
A8: A-Wright | F8: =SUM(B8*2+D8*2) -> 0 | I8: =G8/H8 -> #DIV/0!
A9: VRI-Angwin | F9: =SUM(B9*2+D9*2) -> 0 | I9: =G9/H9 -> #DIV/0!
A12: Round 1
B13: Airport-1-W | D13: Defeated | E13: VRI-1-Wright | G13: Score | H13: Breaks +20
B14: Eric Worsley | D14: Defeated | E14: Graeme Wright
B15: Mick Williams | D15: Defeated | E15: Jayson McLean
B16: David Palmer | D16: Defeated | E16: Jason Smiley
B17: Ben Cahill | D17: Defeated | E17: Stuart Page
B20: VRI-2-Bridges | D20: Defeated | E20: OCC-1 | G20: Score | H20: Breaks +20
B21: Rohan Liston | D21: Defeated | E21: Ivan Crowley
B22: Neville Harty | D22: Defeated | E22: Wayne Clack
B23: Ron Callender | D23: Defeated | E23: John Lewis
B24: Dale Bridges | D24: Defeated | E24: John Grubb
B27: OCC-2 | D27: Defeated | E27: Airport-2-G | G27: Score | H27: Breaks +20
B28: John Eltringham | D28: Defeated | E28: Steve Bagshaw
B29: Geoff Lockyer | D29: Defeated | E29: Craig Bennett
B30: Peter Oates | D30: Defeated | E30: Rod Mc Callum
B31: Geoff Challis | D31: Defeated | E31: Las Ifca
